<?xml version="1.0"?>
<robot xmlns:xacro="http://www.ros.org/wiki/xacro" >
<!-- Wheels Xacros-->
    <xacro:macro name="wheel" params="prefix x_reflect y_reflect">
        <link name="${prefix}_link">
            <visual>
                <origin xyz="0 0 0" rpy="${pi/2} 0 0"/>
                <geometry>
                    <cylinder radius="${wheel_radius}" length="${wheel_width}"/>
                </geometry>
                <material name="red"/>
            </visual>

            <collision>
                <origin xyz="0 0 0" rpy="${pi/2} 0 0"/> 
                <geometry>
                    <cylinder radius="${wheel_radius}" length="${wheel_width}"/>
                </geometry>
            </collision>

            <xacro:cylinder_inertia m="0.5" r="${wheel_radius}" h="${wheel_width}"/>
        </link>

        <joint name="${prefix}_joint" type="continuous">
        <!-- <joint name="${prefix}_joint" type="fixed"> -->
            <parent link="base_link"/>
            <child link="${prefix}_link"/>
            <origin xyz="${x_reflect*wheel_xoff} ${y_reflect*((base_width/2)+wheel_ygap)} ${-wheel_zoff}" rpy="0 0 0"/>
            <!-- <axis xyz="0 0 3"/> -->
        </joint>

        <gazebo reference="${prefix}">
            <material>Gazebo/Grey</material>
        </gazebo>
    </xacro:macro>
</robot>